

























































































455/455 [==============================] - 185s 398ms/step - loss: 7.4610



























































































455/455 [==============================] - 184s 404ms/step - loss: 6.2309



























































































455/455 [==============================] - 184s 404ms/step - loss: 5.9806








 39/455 [=>............................] - ETA: 2:53 - loss: 5.8926
Traceback (most recent call last):
  File "/tmp/ipykernel_274248/418798873.py", line 45, in trainING
    history = model.fit(generator, epochs=1, steps_per_epoch=steps, verbose=1)
              ^^^^^^^^^^^^^^^^^^^^^^^^^^^^^^^^^^^^^^^^^^^^^^^^^^^^^^^^^^^^^^^^
  File "/home/robert/miniconda3/envs/gpu/lib/python3.11/site-packages/keras/src/utils/traceback_utils.py", line 70, in error_handler
    raise e.with_traceback(filtered_tb) from None
  File "/home/robert/miniconda3/envs/gpu/lib/python3.11/site-packages/tensorflow/python/eager/execute.py", line 59, in quick_execute
    except TypeError as e:
Exception